Workbook

Sheet Queries
A1: dataset | B1: scene_id | C1: qid | D1: global_id | E1: category | F1: type | G1: question | H1: options_json | I1: gt_answer | J1: model_answer | K1: is_correct | L1: is_false_positive | M1: notes | N1: rationale
A2: dataset_20260311_144524.json | B2: 1 | C2: Q1 | D2: S1_Q1 | E2: temporal | F2: exact | G2: What time did the user clock in for their library volunteer shift? | I2: 14:00 | J2: Unknown | K2: =IF(LOWER(TRIM(J2))=LOWER(TRIM(I2)),1,0) -> 0 | L2: =IF(AND(LOWER(TRIM(E2))="hallucination",LOWER(TRIM(I2))="no",LOWER(TRIM(J2))="yes"),1,0) -> 0 | N2: The user mentioned 'Okay, I'm clocking in now' in a message sent at 13:57, and the calendar event for the Library Volunteer Shift starts at 14:00.
A3: dataset_20260311_144524.json | B3: 1 | C3: Q2 | D3: S1_Q2 | E3: temporal | F3: binary | G3: Did the user arrive at the library before 14:05? | I3: Yes | J3: Yes | K3: =IF(LOWER(TRIM(J3))=LOWER(TRIM(I3)),1,0) -> 1 | L3: =IF(AND(LOWER(TRIM(E3))="hallucination",LOWER(TRIM(I3))="no",LOWER(TRIM(J3))="yes"),1,0) -> 0 | N3: The GPS data shows the user's location changing at 14:05, and a message sent at 13:57 mentions heading to the library, indicating arrival before 14:05.
A4: dataset_20260311_144524.json | B4: 1 | C4: Q3 | D4: S1_Q3 | E4: cross_modal | F4: multiple_choice | G4: What was the user's heart rate when they mentioned being great? | H4: {"A": "78 bpm", "B": "85 bpm", "C": "90 bpm", "D": "60 bpm"} | I4: A | J4: B | K4: =IF(LOWER(TRIM(J4))=LOWER(TRIM(I4)),1,0) -> 0 | L4: 1 | N4: The user mentioned 'I'm doing great' in a message received at 13:47, and the smartwatch data shows a heart rate of 78 bpm at 13:55:00.
A5: dataset_20260311_144524.json | B5: 1 | C5: Q4 | D5: S1_Q4 | E5: cross_modal | F5: multiple_choice | G5: What was the user doing when they had 250 steps? | H5: {"A": "Heading to the library", "B": "Walking to the book club meeting", "C": "During the library volunteer shift", "D": "Engaging in a sedentary activity"} | I5: A | J5: C | K5: =IF(LOWER(TRIM(J5))=LOWER(TRIM(I5)),1,0) -> 0 | L5: 1 | N5: The smartwatch data shows 250 steps at 14:05:00, and the user mentioned heading to the library in a message sent at 13:45.
A6: dataset_20260311_144524.json | B6: 1 | C6: Q5 | D6: S1_Q5 | E6: cross_modal | F6: multiple_choice | G6: What was the user's activity level when their heart rate was 90 bpm? | H6: {"A": "Sedentary", "B": "Lightly active", "C": "Moderately active", "D": "Very active"} | I6: C | J6: C | K6: =IF(LOWER(TRIM(J6))=LOWER(TRIM(I6)),1,0) -> 1 | L6: =IF(AND(LOWER(TRIM(E6))="hallucination",LOWER(TRIM(I6))="no",LOWER(TRIM(J6))="yes"),1,0) -> 0 | N6: The smartwatch data shows 600 steps and 25 active minutes at 14:20:00, indicating moderate activity when the heart rate was 90 bpm.
A7: dataset_20260311_144524.json | B7: 1 | C7: Q6 | D7: S1_Q6 | E7: deduplication | F7: exact | G7: How many unique volunteer shifts were mentioned? | I7: 1 | J7: 1 | K7: =IF(LOWER(TRIM(J7))=LOWER(TRIM(I7)),1,0) -> 1 | L7: =IF(AND(LOWER(TRIM(E7))="hallucination",LOWER(TRIM(I7))="no",LOWER(TRIM(J7))="yes"),1,0) -> 0 | N7: The calendar event and the user's message both refer to the same library volunteer shift, resulting in a count of 1 unique event.
A8: dataset_20260311_144524.json | B8: 1 | C8: Q7 | D8: S1_Q7 | E8: hallucination | F8: binary | G8: Did the user attend a yoga class? | I8: No | J8: No | K8: =IF(LOWER(TRIM(J8))=LOWER(TRIM(I8)),1,0) -> 1 | L8: =IF(AND(LOWER(TRIM(E8))="hallucination",LOWER(TRIM(I8))="no",LOWER(TRIM(J8))="yes"),1,0) -> 0 | N8: There is no mention of a yoga class in the provided data.
A9: dataset_20260311_144524.json | B9: 1 | C9: Q8 | D9: S1_Q8 | E9: hallucination | F9: binary | G9: Did the user meet a friend at a coffee shop before the library? | I9: No | J9: No | K9: =IF(LOWER(TRIM(J9))=LOWER(TRIM(I9)),1,0) -> 1 | L9: =IF(AND(LOWER(TRIM(E9))="hallucination",LOWER(TRIM(I9))="no",LOWER(TRIM(J9))="yes"),1,0) -> 0 | N9: There is no mention of meeting a friend at a coffee shop before the library in the provided data.
A10: dataset_20260311_144524.json | B10: 2 | C10: Q1 | D10: S2_Q1 | E10: temporal | F10: exact | G10: What time did the user start their walk? | I10: 08:00:00 | J10: 08:00:00 | K10: =IF(LOWER(TRIM(J10))=LOWER(TRIM(I10)),1,0) -> 1 | L10: =IF(AND(LOWER(TRIM(E10))="hallucination",LOWER(TRIM(I10))="no",LOWER(TRIM(J10))="yes"),1,0) -> 0 | N10: The user's smartwatch data shows a change in activity at 08:00:00, and the dialogue mentions 'I'm going for a walk around the block first.' The GPS data also shows a speed of 0.0 at 08:00:00, indicating the user was stationary before starting the walk.
A11: dataset_20260311_144524.json | B11: 2 | C11: Q2 | D11: S2_Q2 | E11: temporal | F11: binary | G11: Did the user send a message to John before 08:45? | I11: No | J11: Yes | K11: =IF(LOWER(TRIM(J11))=LOWER(TRIM(I11)),1,0) -> 0 | L11: 1 | N11: The message to John was sent at 08:45, as shown in the messages data. Therefore, the user did not send a message to John before 08:45.
A12: dataset_20260311_144524.json | B12: 2 | C12: Q3 | D12: S2_Q3 | E12: cross_modal | F12: multiple_choice | G12: What was the user doing when they mentioned needing fresh air? | H12: {"A": "Walking (according to steps data)", "B": "Eating oatmeal", "C": "Reading a book", "D": "Sending a message"} | I12: A | J12: A | K12: =IF(LOWER(TRIM(J12))=LOWER(TRIM(I12)),1,0) -> 1 | L12: =IF(AND(LOWER(TRIM(E12))="hallucination",LOWER(TRIM(I12))="no",LOWER(TRIM(J12))="yes"),1,0) -> 0 | N12: The user mentioned needing fresh air at the beginning of the dialogue, and the smartwatch data shows that they started walking at 08:00:00, which aligns with the start of their walk.
A13: dataset_20260311_144524.json | B13: 2 | C13: Q4 | D13: S2_Q4 | E13: cross_modal | F13: multiple_choice | G13: What was the user's heart rate when they mentioned having oatmeal with fruit? | H13: {"A": "65 bpm", "B": "75 bpm", "C": "80 bpm", "D": "Cannot determine"} | I13: D | J13: D | K13: =IF(LOWER(TRIM(J13))=LOWER(TRIM(I13)),1,0) -> 1 | L13: =IF(AND(LOWER(TRIM(E13))="hallucination",LOWER(TRIM(I13))="no",LOWER(TRIM(J14))="yes"),1,0) -> 0 | N13: The dialogue mentions having oatmeal with fruit, but does not specify the exact time. The smartwatch data shows heart rates of 65, 75, and 80 bpm at different times, but it is not possible to determine which one corresponds to the user having oatmeal.
A14: dataset_20260311_144524.json | B14: 2 | C14: Q5 | D14: S2_Q5 | E14: cross_modal | F14: multiple_choice | G14: What activity was the user doing when their heart rate was 80 bpm? | H14: {"A": "Walking (according to steps data)", "B": "Reading a book", "C": "Eating oatmeal", "D": "Sending a message"} | I14: A | J14: A | K14: =IF(LOWER(TRIM(J14))=LOWER(TRIM(I14)),1,0) -> 1 | L14: =IF(AND(LOWER(TRIM(E14))="hallucination",LOWER(TRIM(I14))="no",LOWER(TRIM(J15))="yes"),1,0) -> 0 | N14: The smartwatch data shows that the user's heart rate was 80 bpm at 08:20:00, and the steps data indicates that the user was walking at this time.
A15: dataset_20260311_144524.json | B15: 2 | C15: Q6 | D15: S2_Q6 | E15: deduplication | F15: exact | G15: How many unique messages did the user send? | I15: 3 | J15: Unknown | K15: =IF(LOWER(TRIM(J15))=LOWER(TRIM(I15)),1,0) -> 0 | L15: =IF(AND(LOWER(TRIM(E15))="hallucination",LOWER(TRIM(I15))="no",LOWER(TRIM(J15))="yes"),1,0) -> 0 | N15: The messages data shows that the user sent messages to Emily, Sarah is a received message, and John, and Library Volunteer Group and and 3 messages were sent .
A16: dataset_20260311_144524.json | B16: 2 | C16: Q7 | D16: S2_Q7 | E16: hallucination | F16: binary | G16: Did the user go to the movies? | I16: No | J16: No | K16: =IF(LOWER(TRIM(J16))=LOWER(TRIM(I16)),1,0) -> 1 | L16: =IF(AND(LOWER(TRIM(E16))="hallucination",LOWER(TRIM(I16))="no",LOWER(TRIM(J16))="yes"),1,0) -> 0 | N16: There is no mention of the user going to the movies in the provided data.
A17: dataset_20260311_144524.json | B17: 2 | C17: Q8 | D17: S2_Q8 | E17: hallucination | F17: binary | G17: Did the user attend a yoga class? | I17: No | J17: No | K17: =IF(LOWER(TRIM(J17))=LOWER(TRIM(I17)),1,0) -> 1 | L17: =IF(AND(LOWER(TRIM(E17))="hallucination",LOWER(TRIM(I17))="no",LOWER(TRIM(J17))="yes"),1,0) -> 0 | N17: There is no mention of the user attending a yoga class in the provided data.
A18: dataset_20260311_144524.json | B18: 3 | C18: Q1 | D18: S3_Q1 | E18: temporal | F18: exact | G18: What time did Susan pick up Linda? | I18: 18:50 | J18: Unknown | K18: =IF(LOWER(TRIM(J18))=LOWER(TRIM(I18)),1,0) -> 0 | L18: =IF(AND(LOWER(TRIM(E18))="hallucination",LOWER(TRIM(I18))="no",LOWER(TRIM(J18))="yes"),1,0) -> 0 | N18: According to the WhatsApp messages, Linda sent 'Hi Susan! Sorry I'm not ready yet' at 18:50, indicating Susan arrived at this time.
A19: dataset_20260311_144524.json | B19: 3 | C19: Q2 | D19: S3_Q2 | E19: temporal | F19: binary | G19: Did Linda finish making tea before 18:20? | I19: No | J19: No | K19: =IF(LOWER(TRIM(J19))=LOWER(TRIM(I19)),1,0) -> 1 | L19: =IF(AND(LOWER(TRIM(E19))="hallucination",LOWER(TRIM(I19))="no",LOWER(TRIM(J19))="yes"),1,0) -> 0 | N19: The dialogue indicates Linda was making tea while talking, and there's no mention of her finishing before 18:20. The smartwatch data at 18:20 shows normal activity, not indicating a significant pause for tea-making.
A20: dataset_20260311_144524.json | B20: 3 | C20: Q3 | D20: S3_Q3 | E20: cross_modal | F20: multiple_choice | G20: What was Linda doing while talking to Susan according to her dialogue and smartwatch data? | H20: {"A": "Making tea and checking notes", "B": "Gardening", "C": "Reading a book", "D": "Watching TV"} | I20: A | J20: A | K20: =IF(LOWER(TRIM(J20))=LOWER(TRIM(I20)),1,0) -> 1 | L20: =IF(AND(LOWER(TRIM(E20))="hallucination",LOWER(TRIM(I20))="no",LOWER(TRIM(J20))="yes"),1,0) -> 0 | N20: Linda's dialogue mentions 'I'm making some tea and checking my notes on the latest book.' The smartwatch data shows increased activity minutes, consistent with her actions.
A21: dataset_20260311_144524.json | B21: 3 | C21: Q4 | D21: S3_Q4 | E21: cross_modal | F21: multiple_choice | G21: How did Susan's day go according to her message to Linda? | H21: {"A": "Busy with gardening", "B": "Busy with work", "C": "Relaxing at home", "D": "Traveling"} | I21: A | J21: B | K21: =IF(LOWER(TRIM(J21))=LOWER(TRIM(I21)),1,0) -> 0 | L21: 1 | N21: Susan's message to Linda states, 'It was fine just busy with some gardening.'
A22: dataset_20260311_144524.json | B22: 3 | C22: Q5 | D22: S3_Q5 | E22: cross_modal | F22: multiple_choice | G22: What was Linda's heart rate when she was getting ready for the book club meeting? | H22: {"A": "80 bpm", "B": "85 bpm", "C": "90 bpm", "D": "95 bpm"} | I22: A | J22: B | K22: =IF(LOWER(TRIM(J22))=LOWER(TRIM(I22)),1,0) -> 0 | L22: 1 | N22: According to the smartwatch data at 18:00:00, Linda's heart rate was 80 bpm while getting ready.
A23: dataset_20260311_144524.json | B23: 3 | C23: Q6 | D23: S3_Q6 | E23: deduplication | F23: exact | G23: How many unique events of gardening are mentioned? | I23: 1 | J23: 1 | K23: =IF(LOWER(TRIM(J23))=LOWER(TRIM(I23)),1,0) -> 1 | L23: =IF(AND(LOWER(TRIM(E23))="hallucination",LOWER(TRIM(I23))="no",LOWER(TRIM(J23))="yes"),1,0) -> 0 | N23: Susan mentions gardening twice but it's the same event, so it counts as 1 unique event.
A24: dataset_20260311_144524.json | B24: 3 | C24: Q7 | D24: S3_Q7 | E24: hallucination | F24: binary | G24: Did Linda go to the movies that evening? | I24: No | J24: No | K24: =IF(LOWER(TRIM(J24))=LOWER(TRIM(I24)),1,0) -> 1 | L24: =IF(AND(LOWER(TRIM(E24))="hallucination",LOWER(TRIM(I24))="no",LOWER(TRIM(J24))="yes"),1,0) -> 0 | N24: There is no mention of Linda going to the movies in the provided data.
A25: dataset_20260311_144524.json | B25: 3 | C25: Q8 | D25: S3_Q8 | E25: hallucination | F25: binary | G25: Did Susan go to a concert that evening? | I25: No | J25: No | K25: =IF(LOWER(TRIM(J25))=LOWER(TRIM(I25)),1,0) -> 1 | L25: =IF(AND(LOWER(TRIM(E25))="hallucination",LOWER(TRIM(I25))="no",LOWER(TRIM(J25))="yes"),1,0) -> 0 | N25: There is no mention of Susan going to a concert in the provided data.
A26: dataset_20260311_144524.json | B26: 4 | C26: Q1 | D26: S4_Q1 | E26: temporal | F26: exact | G26: What time did Linda send the message 'Not much, just getting ready for the weekend. How about you?' to Susan? | I26: 18:07 | J26: 0.75486111 | K26: =IF(LOWER(TRIM(J26))=LOWER(TRIM(I26)),1,0) -> 0 | L26: =IF(AND(LOWER(TRIM(E26))="hallucination",LOWER(TRIM(I26))="no",LOWER(TRIM(J26))="yes"),1,0) -> 0 | N26: The message was sent at 18:07 according to the WhatsApp messages data.
A27: dataset_20260311_144524.json | B27: 4 | C27: Q2 | D27: S4_Q2 | E27: temporal | F27: binary | G27: Did Linda have a lunch date with Susan before 12:00 today? | I27: No | J27: No | K27: =IF(LOWER(TRIM(J27))=LOWER(TRIM(I27)),1,0) -> 1 | L27: =IF(AND(LOWER(TRIM(E27))="hallucination",LOWER(TRIM(I27))="no",LOWER(TRIM(J27))="yes"),1,0) -> 0 | N27: The calendar event for 'Lunch with Susan' is scheduled from 12:00, so it did not happen before 12:00.
A28: dataset_20260311_144524.json | B28: 4 | C28: Q3 | D28: S4_Q3 | E28: cross_modal | F28: multiple_choice | G28: What was Linda doing while her heart rate was 75 and she took 150 steps? | H28: {"A": "Getting ready for her lunch date", "B": "Discussing weekend plans with Susan", "C": "Pruning roses in the garden", "D": "Eating lunch at The Bistro"} | I28: A | J28: C | K28: =IF(LOWER(TRIM(J28))=LOWER(TRIM(I28)),1,0) -> 0 | L28: 1 | N28: Linda mentioned getting ready for her lunch date and the smartwatch data shows a heart rate of 75 and 150 steps at 14:00:00.
A29: dataset_20260311_144524.json | B29: 4 | C29: Q4 | D29: S4_Q4 | E29: cross_modal | F29: multiple_choice | G29: What did Linda mention she loves hearing about? | H29: {"A": "Susan's gardening experiences", "B": "Susan's travels", "C": "Susan's work life", "D": "Susan's favorite books"} | I29: B | J29: B | K29: =IF(LOWER(TRIM(J29))=LOWER(TRIM(I29)),1,0) -> 1 | L29: =IF(AND(LOWER(TRIM(E29))="hallucination",LOWER(TRIM(I29))="no",LOWER(TRIM(J29))="yes"),1,0) -> 0 | N29: Linda explicitly mentioned 'I love hearing about her travels.' in the dialogue.
A30: dataset_20260311_144524.json | B30: 4 | C30: Q5 | D30: S4_Q5 | E30: cross_modal | F30: multiple_choice | G30: What activity did Linda consider doing this weekend? | H30: {"A": "Trying a new restaurant downtown", "B": "Going to the gym", "C": "Pruning roses in the garden", "D": "Watching a movie"} | I30: C | J30: C | K30: =IF(LOWER(TRIM(J30))=LOWER(TRIM(I30)),1,0) -> 1 | L30: =IF(AND(LOWER(TRIM(E30))="hallucination",LOWER(TRIM(I30))="no",LOWER(TRIM(J30))="yes"),1,0) -> 0 | N30: Linda mentioned 'I'm thinking of getting some gardening done this weekend. The roses need pruning.'
A31: dataset_20260311_144524.json | B31: 4 | C31: Q6 | D31: S4_Q6 | E31: deduplication | F31: exact | G31: How many unique events of sending messages to Susan did Linda do? | I31: 3 | J31: 3 | K31: =IF(LOWER(TRIM(J31))=LOWER(TRIM(I31)),1,0) -> 1 | L31: =IF(AND(LOWER(TRIM(E31))="hallucination",LOWER(TRIM(I31))="no",LOWER(TRIM(J31))="yes"),1,0) -> 0 | N31: Linda sent 3 messages to Susan at different timestamps: 18:07, 18:11, and 18:05 is a received message, so not counted.
A32: dataset_20260311_144524.json | B32: 4 | C32: Q7 | D32: S4_Q7 | E32: hallucination | F32: binary | G32: Did Linda go to the movies with Susan yesterday? | I32: No | J32: No | K32: =IF(LOWER(TRIM(J32))=LOWER(TRIM(I32)),1,0) -> 1 | L32: =IF(AND(LOWER(TRIM(E32))="hallucination",LOWER(TRIM(I32))="no",LOWER(TRIM(J32))="yes"),1,0) -> 0 | N32: There is no mention of Linda and Susan going to the movies in the provided data.
A33: dataset_20260311_144524.json | B33: 4 | C33: Q8 | D33: S4_Q8 | E33: hallucination | F33: binary | G33: Did Linda attend a yoga class this morning? | I33: No | J33: No | K33: =IF(LOWER(TRIM(J33))=LOWER(TRIM(I33)),1,0) -> 1 | L33: =IF(AND(LOWER(TRIM(E33))="hallucination",LOWER(TRIM(I33))="no",LOWER(TRIM(J33))="yes"),1,0) -> 0 | N33: There is no mention of Linda attending a yoga class in the provided data.
A34: dataset_20260311_144524.json | B34: 5 | C34: Q1 | D34: S5_Q1 | E34: temporal | F34: exact | G34: What time did Linda start discussing the gardening competition with John? | I34: 13:05 | J34: 13:05 | K34: =IF(LOWER(TRIM(J34))=LOWER(TRIM(I34)),1,0) -> 1 | L34: =IF(AND(LOWER(TRIM(E34))="hallucination",LOWER(TRIM(I34))="no",LOWER(TRIM(J34))="yes"),1,0) -> 0 | N34: The first message from John about the garden was received at 13:05.
A35: dataset_20260311_144524.json | B35: 5 | C35: Q2 | D35: S5_Q2 | E35: temporal | F35: binary | G35: Did Linda discuss the gardening competition with John before 14:00? | I35: Yes | J35: Yes | K35: =IF(LOWER(TRIM(J35))=LOWER(TRIM(I35)),1,0) -> 1 | L35: =IF(AND(LOWER(TRIM(E35))="hallucination",LOWER(TRIM(I35))="no",LOWER(TRIM(J35))="yes"),1,0) -> 0 | N35: Messages about the gardening competition were exchanged starting at 13:05, which is before 14:00.
A36: dataset_20260311_144524.json | B36: 5 | C36: Q3 | D36: S5_Q3 | E36: cross_modal | F36: multiple_choice | G36: What was Linda doing while talking to John according to her dialogue and smartwatch data? | H36: {"A": "Running", "B": "Pruning roses", "C": "Cooking", "D": "Watching TV"} | I36: B | J36: B | K36: =IF(LOWER(TRIM(J36))=LOWER(TRIM(I36)),1,0) -> 1 | L36: =IF(AND(LOWER(TRIM(E36))="hallucination",LOWER(TRIM(I36))="no",LOWER(TRIM(J36))="yes"),1,0) -> 0 | N36: Linda mentioned 'Pruning some roses' in her dialogue, and her smartwatch data shows low activity.
A37: dataset_20260311_144524.json | B37: 5 | C37: Q4 | D37: S5_Q4 | E37: cross_modal | F37: multiple_choice | G37: How did Linda's heart rate change during her conversation with John based on smartwatch data? | H37: {"A": "Decreased significantly", "B": "Increased slightly", "C": "Remained stable", "D": "Increased significantly"} | I37: B | J37: D | K37: =IF(LOWER(TRIM(J37))=LOWER(TRIM(I37)),1,0) -> 0 | L37: 1 | N37: Linda's heart rate went from 72 bpm at 14:00 to 80 bpm at 14:10, showing a slight increase.
A38: dataset_20260311_144524.json | B38: 5 | C38: Q5 | D38: S5_Q5 | E38: cross_modal | F38: multiple_choice | G38: What was Linda's location during her conversation with John? | H38: {"A": "Inside her house", "B": "In her garden", "C": "At the local park", "D": "At the gardening competition venue"} | I38: B | J38: B | K38: =IF(LOWER(TRIM(J38))=LOWER(TRIM(I38)),1,0) -> 1 | L38: =IF(AND(LOWER(TRIM(E38))="hallucination",LOWER(TRIM(I38))="no",LOWER(TRIM(J38))="yes"),1,0) -> 0 | N38: Linda mentioned 'I'm in my garden now.' Her GPS data also shows her moving slightly.
A39: dataset_20260311_144524.json | B39: 5 | C39: Q6 | D39: S5_Q6 | E39: deduplication | F39: exact | G39: How many unique gardening competition events are mentioned? | I39: 1 | J39: 1 | K39: =IF(LOWER(TRIM(J39))=LOWER(TRIM(I39)),1,0) -> 1 | L39: =IF(AND(LOWER(TRIM(E39))="hallucination",LOWER(TRIM(I39))="no",LOWER(TRIM(J39))="yes"),1,0) -> 0 | N39: The calendar event and dialogue both refer to the same gardening competition advice session with John.
A40: dataset_20260311_144524.json | B40: 5 | C40: Q7 | D40: S5_Q7 | E40: hallucination | F40: binary | G40: Did Linda go to a swimming pool that afternoon? | I40: No | J40: No | K40: =IF(LOWER(TRIM(J40))=LOWER(TRIM(I40)),1,0) -> 1 | L40: =IF(AND(LOWER(TRIM(E40))="hallucination",LOWER(TRIM(I40))="no",LOWER(TRIM(J40))="yes"),1,0) -> 0 | N40: There is no mention of Linda going to a swimming pool in the provided data.
...

Sheet Summary
A1: Metric | B1: Value
A2: #Queries | B2: =ROWS(Queries!A2:A41) -> 40
A3: Overall Accuracy | B3: =AVERAGE(Queries!K2:K41) -> 0.725
A4: FPR | B4: =IF(COUNTA(Queries!A2:A41)=0,0,SUM(Queries!L2:L41)/COUNTA(Queries!A2:A41)) -> 0.175
A5: Triples (n relationships) | B5: 148
A6: Accuracy Temporal | B6: =IF(COUNTIF(Queries!E2:E41,"temporal")=0,"",AVERAGEIF(Queries!E2:E41,"temporal",Queries!K2:K41)) -> 0.6
A7: Accuracy Cross-modal | B7: =IF(COUNTIF(Queries!E2:E41,"cross_modal")=0,"",AVERAGEIF(Queries!E2:E41,"cross_modal",Queries!K2:K41)) -> 0.6
A8: Accuracy Deduplication | B8: =IF(COUNTIF(Queries!E2:E41,"deduplication")=0,"",AVERAGEIF(Queries!E2:E41,"deduplication",Queries!K2:K41)) -> 0.8
A9: Accuracy Hallucination | B9: =IF(COUNTIF(Queries!E2:E41,"hallucination")=0,"",AVERAGEIF(Queries!E2:E41,"hallucination",Queries!K2:K41)) -> 1
A10: Accuracy Completeness | B10: {=IF(SUMPRODUCT(--(Queries!E2:E41<>"hallucination"))=0,"",1-SUMPRODUCT(--(Queries!E2:E41<>"hallucination"),--(((LOWER(TRIM(Queries!J2:J41))="unknown")+(TRIM(Queries!J2:J41)=""))>0))/SUMPRODUCT(--(Queries!E2:E41<>"hallucination")))} -> 0.9
A12: Delta mode | B12: 0
