Workbook

Sheet Queries
A1: dataset | B1: scene_id | C1: qid | D1: global_id | E1: category | F1: type | G1: question | H1: options_json | I1: gt_answer | J1: model_answer | K1: is_correct | L1: is_false_positive | M1: notes | N1: rationale
A2: dataset_20260312_124034.json | B2: 1 | C2: Q1 | D2: S1_Q1 | E2: temporal | F2: exact | G2: What time did James send the message 'See you at the lanes!'? | I2: 09:20 | K2: =IF(LOWER(TRIM(J2))=LOWER(TRIM(I2)),1,0) -> 0 | L2: =IF(AND(LOWER(TRIM(E2))="hallucination",LOWER(TRIM(I2))="no",LOWER(TRIM(J2))="yes"),1,0) -> 0 | N2: The message 'See you at the lanes!' was sent at 09:20 according to the WhatsApp messages.
A3: dataset_20260312_124034.json | B3: 1 | C3: Q2 | D3: S1_Q2 | E3: temporal | F3: binary | G3: Did James leave the house before 09:15? | I3: No | K3: =IF(LOWER(TRIM(J3))=LOWER(TRIM(I3)),1,0) -> 0 | L3: =IF(AND(LOWER(TRIM(E3))="hallucination",LOWER(TRIM(I3))="no",LOWER(TRIM(J3))="yes"),1,0) -> 0 | N3: James sent a message at 09:05 and 09:08, and his smartwatch data starts at 09:00, indicating he was at home at 09:00. The smartwatch data at 09:15 shows he was active and had taken steps, indicating he had left the house after 09:00 but the exact time of leaving is not before 09:15.
A4: dataset_20260312_124034.json | B4: 1 | C4: Q3 | D4: S1_Q3 | E4: cross_modal | F4: multiple_choice | G4: What was James trying to do before meeting the guys according to his dialogue? | H4: {"A": "Get some breakfast", "B": "Watch TV", "C": "Play video games", "D": "Read a book"} | I4: A | K4: =IF(LOWER(TRIM(J4))=LOWER(TRIM(I4)),1,0) -> 0 | L4: =IF(AND(LOWER(TRIM(E4))="hallucination",LOWER(TRIM(I4))="no",LOWER(TRIM(J4))="yes"),1,0) -> 0 | N4: James mentioned in his dialogue 'I'm good just trying to get some breakfast before we bowl.' This directly supports option A.
A5: dataset_20260312_124034.json | B5: 1 | C5: Q4 | D5: S1_Q4 | E5: cross_modal | F5: multiple_choice | G5: How did James feel about the competition according to his dialogue? | H5: {"A": "He was worried", "B": "He was looking forward to it", "C": "He was indifferent", "D": "He was angry"} | I5: B | K5: =IF(LOWER(TRIM(J5))=LOWER(TRIM(I5)),1,0) -> 0 | L5: =IF(AND(LOWER(TRIM(E5))="hallucination",LOWER(TRIM(I5))="no",LOWER(TRIM(J5))="yes"),1,0) -> 0 | N5: James said 'Oh yeah? I'm looking forward to it then.' This shows he was looking forward to the competition.
A6: dataset_20260312_124034.json | B6: 1 | C6: Q5 | D6: S1_Q5 | E6: cross_modal | F6: multiple_choice | G6: What activity did James and his friends plan to do at 10 AM according to the calendar and dialogue? | H6: {"A": "Go to the gym", "B": "Go bowling", "C": "Have breakfast", "D": "Watch a movie"} | I6: B | K6: =IF(LOWER(TRIM(J6))=LOWER(TRIM(I6)),1,0) -> 0 | L6: =IF(AND(LOWER(TRIM(E6))="hallucination",LOWER(TRIM(I6))="no",LOWER(TRIM(J6))="yes"),1,0) -> 0 | N6: The calendar event is titled 'Bowling with the Guys' starting at 10:00, and the dialogue mentions 'before we bowl.' This supports option B.
A7: dataset_20260312_124034.json | B7: 1 | C7: Q6 | D7: S1_Q6 | E7: deduplication | F7: exact | G7: How many unique messages did James send to Mike? | I7: 4 | K7: =IF(LOWER(TRIM(J7))=LOWER(TRIM(I7)),1,0) -> 0 | L7: =IF(AND(LOWER(TRIM(E7))="hallucination",LOWER(TRIM(I7))="no",LOWER(TRIM(J7))="yes"),1,0) -> 0 | N7: James sent the following messages to Mike: 'Hey Mike! How's it going?', 'I'm good just trying to get some breakfast before we bowl.', 'Oh yeah? I'm looking forward to it then.', and 'See you at the lanes!'. There are 4 unique messages.
A8: dataset_20260312_124034.json | B8: 1 | C8: Q7 | D8: S1_Q7 | E8: hallucination | F8: binary | G8: Did James go to the cinema on Sunday morning? | I8: No | K8: =IF(LOWER(TRIM(J8))=LOWER(TRIM(I8)),1,0) -> 0 | L8: =IF(AND(LOWER(TRIM(E8))="hallucination",LOWER(TRIM(I8))="no",LOWER(TRIM(J8))="yes"),1,0) -> 0 | N8: There is no mention of James going to the cinema in the provided data. All activities mentioned involve bowling or morning interactions with Mike.
A9: dataset_20260312_124034.json | B9: 1 | C9: Q8 | D9: S1_Q8 | E9: hallucination | F9: binary | G9: Did James have a meeting at the office on Sunday? | I9: No | K9: =IF(LOWER(TRIM(J9))=LOWER(TRIM(I9)),1,0) -> 0 | L9: =IF(AND(LOWER(TRIM(E9))="hallucination",LOWER(TRIM(I9))="no",LOWER(TRIM(J9))="yes"),1,0) -> 0 | N9: The provided data does not mention James having a meeting at the office. The activities mentioned are bowling with friends and morning interactions.
A10: dataset_20260312_124034.json | B10: 2 | C10: Q1 | D10: S2_Q1 | E10: temporal | F10: exact | G10: What time did the user clock in for their shift? | I10: Not explicitly mentioned | K10: =IF(LOWER(TRIM(J10))=LOWER(TRIM(I10)),1,0) -> 0 | L10: =IF(AND(LOWER(TRIM(E10))="hallucination",LOWER(TRIM(I10))="no",LOWER(TRIM(J10))="yes"),1,0) -> 0 | N10: The scene description mentions 'I'm clocking in for my shift.' but does not provide a specific time. The earliest timestamp provided is 14:00:00 from sensor data.
A11: dataset_20260312_124034.json | B11: 2 | C11: Q2 | D11: S2_Q2 | E11: temporal | F11: binary | G11: Did the user grab a snack before 14:10:00? | I11: Yes | K11: =IF(LOWER(TRIM(J11))=LOWER(TRIM(I11)),1,0) -> 0 | L11: =IF(AND(LOWER(TRIM(E11))="hallucination",LOWER(TRIM(I11))="no",LOWER(TRIM(J11))="yes"),1,0) -> 0 | N11: The user mentions 'I'm gonna go grab a snack before we get started' in a message sent at 14:08, and the smartwatch data shows an entry at 14:10:00, indicating the snack was grabbed before this time.
A12: dataset_20260312_124034.json | B12: 2 | C12: Q3 | D12: S2_Q3 | E12: cross_modal | F12: multiple_choice | G12: What did the user plan to do during their break according to the dialogue? | H12: {"A": "Sneak in a walk", "B": "Check notifications on their smartphone", "C": "Use a productivity app", "D": "Read a book"} | I12: A | K12: =IF(LOWER(TRIM(J12))=LOWER(TRIM(I12)),1,0) -> 0 | L12: =IF(AND(LOWER(TRIM(E12))="hallucination",LOWER(TRIM(I12))="no",LOWER(TRIM(J12))="yes"),1,0) -> 0 | N12: The user mentions 'Maybe I'll try to sneak in a walk during my break to make up for it.' This directly supports option A.
A13: dataset_20260312_124034.json | B13: 2 | C13: Q4 | D13: S2_Q4 | E13: cross_modal | F13: multiple_choice | G13: What type of food did the user consider eating according to the dialogue? | H13: {"A": "A salad", "B": "A burger from the food truck", "C": "A sandwich from the cafeteria", "D": "Fries from a restaurant"} | I13: A | K13: =IF(LOWER(TRIM(J13))=LOWER(TRIM(I13)),1,0) -> 0 | L13: =IF(AND(LOWER(TRIM(E13))="hallucination",LOWER(TRIM(I13))="no",LOWER(TRIM(J13))="yes"),1,0) -> 0 | N13: The user mentions 'Ugh I could really use a salad or something healthy but I think I'm gonna grab a burger from the food truck instead.' This directly supports option A as a considered food type.
A14: dataset_20260312_124034.json | B14: 2 | C14: Q5 | D14: S2_Q5 | E14: cross_modal | F14: multiple_choice | G14: Where is the break room located according to the dialogue? | H14: {"A": "Second door on the right", "B": "Third door on the left", "C": "First door on the right", "D": "At the end of the hall"} | I14: B | K14: =IF(LOWER(TRIM(J14))=LOWER(TRIM(I14)),1,0) -> 0 | L14: =IF(AND(LOWER(TRIM(E14))="hallucination",LOWER(TRIM(I14))="no",LOWER(TRIM(J14))="yes"),1,0) -> 0 | N14: The dialogue mentions 'Third door on your left' as the location of the break room, directly supporting option B.
A15: dataset_20260312_124034.json | B15: 2 | C15: Q6 | D15: S2_Q6 | E15: deduplication | F15: exact | G15: How many unique mentions of going to the food truck are there? | I15: 1 | K15: =IF(LOWER(TRIM(J15))=LOWER(TRIM(I15)),1,0) -> 0 | L15: =IF(AND(LOWER(TRIM(E15))="hallucination",LOWER(TRIM(I15))="no",LOWER(TRIM(J15))="yes"),1,0) -> 0 | N15: The dialogue only mentions going to the food truck once: 'Ugh I could really use a salad or something healthy but I think I'm gonna grab a burger from the food truck instead.'
A16: dataset_20260312_124034.json | B16: 2 | C16: Q7 | D16: S2_Q7 | E16: hallucination | F16: binary | G16: Did the user attend a meeting? | I16: No | K16: =IF(LOWER(TRIM(J16))=LOWER(TRIM(I16)),1,0) -> 0 | L16: =IF(AND(LOWER(TRIM(E16))="hallucination",LOWER(TRIM(I16))="no",LOWER(TRIM(J16))="yes"),1,0) -> 0 | N16: There is no mention of attending a meeting in the provided dialogue or data.
A17: dataset_20260312_124034.json | B17: 2 | C17: Q8 | D17: S2_Q8 | E17: hallucination | F17: binary | G17: Did the user go skydiving? | I17: No | K17: =IF(LOWER(TRIM(J17))=LOWER(TRIM(I17)),1,0) -> 0 | L17: =IF(AND(LOWER(TRIM(E17))="hallucination",LOWER(TRIM(I17))="no",LOWER(TRIM(J17))="yes"),1,0) -> 0 | N17: There is no mention of skydiving in the provided dialogue or data.
A18: dataset_20260312_124034.json | B18: 3 | C18: Q1 | D18: S3_Q1 | E18: temporal | F18: exact | G18: What time did the user send the message 'I'm heading home from work now.'? | I18: 17:00 | K18: =IF(LOWER(TRIM(J18))=LOWER(TRIM(I18)),1,0) -> 0 | L18: =IF(AND(LOWER(TRIM(E18))="hallucination",LOWER(TRIM(I18))="no",LOWER(TRIM(J18))="yes"),1,0) -> 0 | N18: The user's message 'I'm heading home from work now.' is not directly provided with a timestamp, but based on the provided messages and their timestamps, the earliest message sent is at 17:05. However, the scene description and messages indicate the user was heading home from work around this time. The smartwatch and GPS data start at 17:00:00, suggesting this is the time frame in question.
A19: dataset_20260312_124034.json | B19: 3 | C19: Q2 | D19: S3_Q2 | E19: temporal | F19: binary | G19: Did the user mention grabbing dinner before 17:30? | I19: Yes | K19: =IF(LOWER(TRIM(J19))=LOWER(TRIM(I19)),1,0) -> 0 | L19: =IF(AND(LOWER(TRIM(E19))="hallucination",LOWER(TRIM(I19))="no",LOWER(TRIM(J19))="yes"),1,0) -> 0 | N19: The user mentioned 'I'm gonna grab some dinner on the way.' in the dialogue. The messages and smartwatch/GPS data indicate this conversation and activities happened around and after 17:00, with a message sent at 17:20 discussing grabbing a burger.
A20: dataset_20260312_124034.json | B20: 3 | C20: Q3 | D20: S3_Q3 | E20: cross_modal | F20: multiple_choice | G20: What was the user's heart rate when they mentioned having a conversation with Samantha? | H20: {"A": "80 bpm", "B": "85 bpm", "C": "90 bpm", "D": "95 bpm"} | I20: B | K20: =IF(LOWER(TRIM(J20))=LOWER(TRIM(I20)),1,0) -> 0 | L20: =IF(AND(LOWER(TRIM(E20))="hallucination",LOWER(TRIM(I20))="no",LOWER(TRIM(J20))="yes"),1,0) -> 0 | N20: The user had a conversation with Samantha around 17:10 according to the messages. At 17:20:00, the user's heart rate was 85 bpm according to the smartwatch data, which is the closest timestamp to when the conversation occurred.
A21: dataset_20260312_124034.json | B21: 3 | C21: Q4 | D21: S3_Q4 | E21: cross_modal | F21: multiple_choice | G21: What did the user plan to do regarding dinner based on the dialogue? | H21: {"A": "Cook at home", "B": "Order takeout", "C": "Get a burger", "D": "Skip dinner"} | I21: C | K21: =IF(LOWER(TRIM(J21))=LOWER(TRIM(I21)),1,0) -> 0 | L21: =IF(AND(LOWER(TRIM(E21))="hallucination",LOWER(TRIM(I21))="no",LOWER(TRIM(J21))="yes"),1,0) -> 0 | N21: The user explicitly mentioned 'Probably just get a burger or something.' in the dialogue, indicating they planned to get a burger for dinner.
A22: dataset_20260312_124034.json | B22: 3 | C22: Q5 | D22: S3_Q5 | E22: cross_modal | F22: multiple_choice | G22: At what time did the user plan to watch a game with Samantha? | H22: {"A": "8:00 PM", "B": "9:00 PM", "C": "10:00 PM", "D": "11:00 PM"} | I22: B | K22: =IF(LOWER(TRIM(J22))=LOWER(TRIM(I22)),1,0) -> 0 | L22: =IF(AND(LOWER(TRIM(E22))="hallucination",LOWER(TRIM(I22))="no",LOWER(TRIM(J22))="yes"),1,0) -> 0 | N22: The user and Samantha discussed and agreed on 9:00 PM to watch a game. The user asked, 'What time were you thinking?' and Samantha replied, 'How about 9 o'clock?' The user then said, 'Sounds perfect I'll see you then.'
A23: dataset_20260312_124034.json | B23: 3 | C23: Q6 | D23: S3_Q6 | E23: deduplication | F23: exact | G23: How many unique gym sessions were mentioned? | I23: 0 | K23: =IF(LOWER(TRIM(J23))=LOWER(TRIM(I23)),1,0) -> 0 | L23: =IF(AND(LOWER(TRIM(E23))="hallucination",LOWER(TRIM(I23))="no",LOWER(TRIM(J23))="yes"),1,0) -> 0 | N23: There were no gym sessions mentioned in the provided dialogue or data. The user discussed heading home from work, grabbing dinner, and watching a game with Samantha, but did not mention going to the gym.
A24: dataset_20260312_124034.json | B24: 3 | C24: Q7 | D24: S3_Q7 | E24: hallucination | F24: binary | G24: Did the user go to the movies? | I24: No | K24: =IF(LOWER(TRIM(J24))=LOWER(TRIM(I24)),1,0) -> 0 | L24: =IF(AND(LOWER(TRIM(E24))="hallucination",LOWER(TRIM(I24))="no",LOWER(TRIM(J24))="yes"),1,0) -> 0 | N24: There is no mention of going to the movies in the provided dialogue, messages, or sensor data. The activities mentioned include heading home from work, grabbing dinner, and watching a game with Samantha at home.
A25: dataset_20260312_124034.json | B25: 3 | C25: Q8 | D25: S3_Q8 | E25: hallucination | F25: binary | G25: Did the user attend a meeting at the office? | I25: No | K25: =IF(LOWER(TRIM(J25))=LOWER(TRIM(I25)),1,0) -> 0 | L25: =IF(AND(LOWER(TRIM(E25))="hallucination",LOWER(TRIM(I25))="no",LOWER(TRIM(J25))="yes"),1,0) -> 0 | N25: There is no mention of attending a meeting at the office in the provided dialogue, messages, or sensor data. The user discussed heading home from work and other activities but did not mention an office meeting.
A26: dataset_20260312_124034.json | B26: 4 | C26: Q1 | D26: S4_Q1 | E26: temporal | F26: exact | G26: What time did the user arrive at their brother's place? | I26: 18:40:00 | K26: =IF(LOWER(TRIM(J26))=LOWER(TRIM(I26)),1,0) -> 0 | L26: =IF(AND(LOWER(TRIM(E26))="hallucination",LOWER(TRIM(I26))="no",LOWER(TRIM(J26))="yes"),1,0) -> 0 | N26: According to the GPS data, at 18:40:00, the user's latitude and longitude were 37.7875 and -122.4375 respectively, indicating they were at their brother's place.
A27: dataset_20260312_124034.json | B27: 4 | C27: Q2 | D27: S4_Q2 | E27: temporal | F27: binary | G27: Did the user send a message to their brother before 18:25:00? | I27: Yes | K27: =IF(LOWER(TRIM(J27))=LOWER(TRIM(I27)),1,0) -> 0 | L27: =IF(AND(LOWER(TRIM(E27))="hallucination",LOWER(TRIM(I27))="no",LOWER(TRIM(J27))="yes"),1,0) -> 0 | N27: The user sent a message to their brother at 18:20:00, which is before 18:25:00.
A28: dataset_20260312_124034.json | B28: 4 | C28: Q3 | D28: S4_Q3 | E28: cross_modal | F28: multiple_choice | G28: Why did the user mention being starving? | H28: {"A": "They had a long day at work", "B": "They had a gym session", "C": "They skipped breakfast", "D": "They walked a lot"} | I28: A | K28: =IF(LOWER(TRIM(J28))=LOWER(TRIM(I28)),1,0) -> 0 | L28: =IF(AND(LOWER(TRIM(E28))="hallucination",LOWER(TRIM(I28))="no",LOWER(TRIM(J28))="yes"),1,0) -> 0 | N28: The user mentioned 'I'm starving after that shift today', indicating that their hunger is related to their work shift.
A29: dataset_20260312_124034.json | B29: 4 | C29: Q4 | D29: S4_Q4 | E29: cross_modal | F29: multiple_choice | G29: What was the user's brother preparing for dinner? | H29: {"A": "Getting the kids ready", "B": "Cooking a meal", "C": "Setting the table", "D": "Ordering takeout"} | I29: A | K29: =IF(LOWER(TRIM(J29))=LOWER(TRIM(I29)),1,0) -> 0 | L29: =IF(AND(LOWER(TRIM(E29))="hallucination",LOWER(TRIM(I29))="no",LOWER(TRIM(J29))="yes"),1,0) -> 0 | N29: The brother mentioned 'just getting the kids ready' in response to the user's question about what was up.
A30: dataset_20260312_124034.json | B30: 4 | C30: Q5 | D30: S4_Q5 | E30: cross_modal | F30: multiple_choice | G30: What activity did the user's brother's kid want to do? | H30: {"A": "Play with Legos", "B": "Watch a movie", "C": "Play a game", "D": "Go for a walk"} | I30: A | K30: =IF(LOWER(TRIM(J30))=LOWER(TRIM(I30)),1,0) -> 0 | L30: =IF(AND(LOWER(TRIM(E30))="hallucination",LOWER(TRIM(I30))="no",LOWER(TRIM(J30))="yes"),1,0) -> 0 | N30: The user mentioned 'His kid's been wanting to play with Legos'.
A31: dataset_20260312_124034.json | B31: 4 | C31: Q6 | D31: S4_Q6 | E31: deduplication | F31: exact | G31: How many unique events of sending messages to the brother did the user do? | I31: 5 | K31: =IF(LOWER(TRIM(J31))=LOWER(TRIM(I31)),1,0) -> 0 | L31: =IF(AND(LOWER(TRIM(E31))="hallucination",LOWER(TRIM(I31))="no",LOWER(TRIM(J31))="yes"),1,0) -> 0 | N31: The user sent 5 messages to their brother at different timestamps: 18:20, 18:25, 18:27, 18:28, 18:30.
A32: dataset_20260312_124034.json | B32: 4 | C32: Q7 | D32: S4_Q7 | E32: hallucination | F32: binary | G32: Did the user go to the movies? | I32: No | K32: =IF(LOWER(TRIM(J32))=LOWER(TRIM(I32)),1,0) -> 0 | L32: =IF(AND(LOWER(TRIM(E32))="hallucination",LOWER(TRIM(I32))="no",LOWER(TRIM(J32))="yes"),1,0) -> 0 | N32: There is no mention of the user going to the movies in the provided data.
A33: dataset_20260312_124034.json | B33: 4 | C33: Q8 | D33: S4_Q8 | E33: hallucination | F33: binary | G33: Did the user attend a concert? | I33: No | K33: =IF(LOWER(TRIM(J33))=LOWER(TRIM(I33)),1,0) -> 0 | L33: =IF(AND(LOWER(TRIM(E33))="hallucination",LOWER(TRIM(I33))="no",LOWER(TRIM(J33))="yes"),1,0) -> 0 | N33: There is no mention of the user attending a concert in the provided data.
A34: dataset_20260312_124034.json | B34: 5 | C34: Q1 | D34: S5_Q1 | E34: temporal | F34: exact | G34: What time did James get up? | I34: 08:00:00 | K34: =IF(LOWER(TRIM(J34))=LOWER(TRIM(I34)),1,0) -> 0 | L34: =IF(AND(LOWER(TRIM(E34))="hallucination",LOWER(TRIM(I34))="no",LOWER(TRIM(J34))="yes"),1,0) -> 0 | N34: James mentioned getting up early at 8 AM, and the smartwatch data shows the first entry at 08:00:00.
A35: dataset_20260312_124034.json | B35: 5 | C35: Q2 | D35: S5_Q2 | E35: temporal | F35: binary | G35: Did James go for a bike ride before 08:15:00? | I35: No | K35: =IF(LOWER(TRIM(J35))=LOWER(TRIM(I35)),1,0) -> 0 | L35: =IF(AND(LOWER(TRIM(E35))="hallucination",LOWER(TRIM(I35))="no",LOWER(TRIM(J35))="yes"),1,0) -> 0 | N35: James mentioned thinking of going for a bike ride later, but the exact time is not specified. The earliest mention is at 08:04, which is after 08:00:00, and there's no indication it happened before 08:15:00.
A36: dataset_20260312_124034.json | B36: 5 | C36: Q3 | D36: S5_Q3 | E36: cross_modal | F36: multiple_choice | G36: What was James doing at 08:00:00 according to dialogue and smartwatch data? | H36: {"A": "Making pancakes", "B": "Going for a bike ride", "C": "Sleeping", "D": "Watching TV"} | I36: A | K36: =IF(LOWER(TRIM(J36))=LOWER(TRIM(I36)),1,0) -> 0 | L36: =IF(AND(LOWER(TRIM(E36))="hallucination",LOWER(TRIM(I36))="no",LOWER(TRIM(J36))="yes"),1,0) -> 0 | N36: James mentioned making pancakes in the dialogue, and the smartwatch data shows he was active at 08:00:00 with 0 steps, indicating he was likely indoors preparing something.
A37: dataset_20260312_124034.json | B37: 5 | C37: Q4 | D37: S5_Q4 | E37: cross_modal | F37: multiple_choice | G37: How was James feeling at 08:00:00 according to his heart rate? | H37: {"A": "Tired", "B": "Normal", "C": "Stressed", "D": "Excited"} | I37: B | K37: =IF(LOWER(TRIM(J37))=LOWER(TRIM(I37)),1,0) -> 0 | L37: =IF(AND(LOWER(TRIM(E37))="hallucination",LOWER(TRIM(I37))="no",LOWER(TRIM(J37))="yes"),1,0) -> 0 | N37: James' heart rate at 08:00:00 was 65 bpm, which is within the normal resting heart rate range (60-80 bpm), indicating he was likely feeling normal.
A38: dataset_20260312_124034.json | B38: 5 | C38: Q5 | D38: S5_Q5 | E38: cross_modal | F38: multiple_choice | G38: What activity did Samantha suggest James should do with her? | H38: {"A": "Go for a bike ride", "B": "Make pancakes", "C": "Do grocery shopping", "D": "Watch a movie"} | I38: A | K38: =IF(LOWER(TRIM(J38))=LOWER(TRIM(I38)),1,0) -> 0 | L38: =IF(AND(LOWER(TRIM(E38))="hallucination",LOWER(TRIM(I38))="no",LOWER(TRIM(J38))="yes"),1,0) -> 0 | N38: Samantha suggested that James should take her with him on a bike ride, as mentioned in the WhatsApp conversation.
A39: dataset_20260312_124034.json | B39: 5 | C39: Q6 | D39: S5_Q6 | E39: deduplication | F39: exact | G39: How many unique events of going to the market are mentioned? | I39: 1 | K39: =IF(LOWER(TRIM(J39))=LOWER(TRIM(I39)),1,0) -> 0 | L39: =IF(AND(LOWER(TRIM(E39))="hallucination",LOWER(TRIM(I39))="no",LOWER(TRIM(J39))="yes"),1,0) -> 0 | N39: The calendar event mentions grocery shopping at the Local Market, and there's no other mention of going to the market, so the count is 1.
A40: dataset_20260312_124034.json | B40: 5 | C40: Q7 | D40: S5_Q7 | E40: hallucination | F40: binary | G40: Did James go to the beach? | I40: No | K40: =IF(LOWER(TRIM(J40))=LOWER(TRIM(I40)),1,0) -> 0 | L40: =IF(AND(LOWER(TRIM(E40))="hallucination",LOWER(TRIM(I40))="no",LOWER(TRIM(J40))="yes"),1,0) -> 0 | N40: There is no mention of James going to the beach in the provided data.
...

Sheet Summary
A1: Metric | B1: Value
A2: #Queries | B2: =ROWS(Queries!A2:A41) -> 40
A3: Overall Accuracy | B3: =AVERAGE(Queries!K2:K41) -> 0
A4: Hallucination FPR | B4: =IF(COUNTIF(Queries!E2:E41,"hallucination")=0,0,SUM(Queries!L2:L41)/COUNTIF(Queries!E2:E41,"hallucination")) -> 0
A5: Triples (manual)
A6: Accuracy Temporal | B6: =IF(COUNTIF(Queries!E2:E41,"temporal")=0,"",AVERAGEIF(Queries!E2:E41,"temporal",Queries!K2:K41)) -> 0
A7: Accuracy Cross-modal | B7: =IF(COUNTIF(Queries!E2:E41,"cross_modal")=0,"",AVERAGEIF(Queries!E2:E41,"cross_modal",Queries!K2:K41)) -> 0
A8: Accuracy Deduplication | B8: =IF(COUNTIF(Queries!E2:E41,"deduplication")=0,"",AVERAGEIF(Queries!E2:E41,"deduplication",Queries!K2:K41)) -> 0
A9: Accuracy Hallucination | B9: =IF(COUNTIF(Queries!E2:E41,"hallucination")=0,"",AVERAGEIF(Queries!E2:E41,"hallucination",Queries!K2:K41)) -> 0
